Workbook

Sheet Settings
A1: KVM Switch + ST-LINK - combined DigiKey order
A2: Prices: digikey.dk cut tape, fetched 2026-10-09 (listed excl. VAT, VAT added here). Quantities: KiCad BOM export of both schematics (DNP / test points excluded).
A4: Input | B4: Value | C4: Note
A5: KVM Switch boards to build | B5: 2 | C5: Drives the DigiKey Order sheet. Compare options on the Scenarios sheet.
A6: ST-LINK boards to build | B6: 2 | C6: Panel has 10 positions - populate as many as you like.
A7: VAT rate | B7: 0.25 | C7: Danish VAT. Ordering privately, so all totals are shown incl. VAT.
A8: Delivery charge | B8: 185 | C8: digikey.dk: 'A delivery charge of kr. 185 will be billed on all orders less than kr. 550.'
A9: Free delivery from | B9: 550 | C9: digikey.dk: 'Free delivery to Denmark on orders of kr. 550 or more.'
A10: DigiKey's 185 / 550 kr are | B10: excl. VAT | C10: DigiKey doesn't say. 'excl. VAT' is the safe assumption (= 687.50 kr incl. VAT); the checkout cart will confirm.
A12: Order summary (board counts above, incl. VAT)
A13: Parts incl. VAT | B13: ='DigiKey Order'!$R$25 -> 696.6
A14: Order value as DigiKey measures it | B14: =IF(Settings!$B$10="excl. VAT",B13/(1+Settings!$B$7),B13) -> 557.28 | C14: excl. or incl. VAT per B10 - this is what is compared with the 550 kr
A15: Delivery incl. VAT | B15: =IF(B14>=Settings!$B$9,0,Settings!$B$8*IF(Settings!$B$10="excl. VAT",1+Settings!$B$7,1)) -> 0
A16: TOTAL TO PAY incl. VAT | B16: =B13+B15 -> 696.6
A17: Missing to free delivery (incl. VAT) | B17: =MAX(0,Settings!$B$9-B14)*IF(Settings!$B$10="excl. VAT",1+Settings!$B$7,1) -> 0
A18: Advice | B18: =IF(B17=0,"Free delivery reached",IF(B17<B15,"Top up: add "&TEXT(B17,"0")&" kr of parts - cheaper than "&TEXT(B15,"0")&" kr delivery","Pay delivery - topping up would cost more than "&TEXT(B15,"0")&" kr")) -> Free delivery reached
A19: Lines with 0 / low stock | B19: =SUMPRODUCT(('DigiKey Order'!L4:L23="Y")*((LEFT('DigiKey Order'!I4:I23,1)="0")+('DigiKey Order'!I4:I23="14"))) -> 1 | C19: Check 'Stock @ fetch' on the DigiKey Order sheet
A22: How to use
A23: - Yellow cells with blue text are inputs - everything else is calculated.
A24: - Scenarios sheet: totals for every KVM / ST-LINK combination (board counts in its header are editable).
A25: - Pick a combination, enter it in B5/B6 - the DigiKey Order sheet then shows exactly what to put in the cart.
A26: - DigiKey Order: 'Owned' is subtracted from Needed, 'Order?' Y/N, 'Extra' adds spares (use it to top up to free delivery), 'Price override' replaces the looked-up price.
A27: - 'Next break' shows the qty at the next price break and the line cost there - sometimes buying more is cheaper.
A28: - AX Parts / Owned parts: what to pull from stock. Enter 'On hand' to see shortages.
A30: Design notes
A31: - Drop-in replacements chosen for parts out of stock at DigiKey on 2026-10-09 (schematic DigiKey fields still show the old PNs):
A32: - U14 TS3USB221AQRSERQ1 (296-27719-1-ND, 0 stock) -> TS3USB221ERSER (296-25222-1-ND): same RSE 10-UQFN, pinout, S/OE truth table, VCC 2.3-3.6V; ESD-enhanced, not automotive.
A33: - C25 100u: old PN was a 1210 part on a C_1206 footprint and 0 stock -> GRM31CR61A107MEA8L, 100u 10V X5R 1206 (fits the footprint). C25 is on VBUS (5V).
A34: - 5.1k 0603 RC0603FR-075K1L (0 stock) -> Stackpole RMCF0603FT5K10, same value/size/tolerance.
... A39: - ST-LINK J2: 732-5317-ND is a vertical THT header (61300411121), footprint is 'conn_01x04_P2.54_right_smd' - confirm.

Sheet Scenarios
A1: What does each build option cost? (DKK incl. VAT, delivery rules from Settings)
A2: Uses Order?, Extra and Price override from the DigiKey Order sheet; only the board counts change. Edit the yellow board counts to try other combinations.
A4: KVM boards | C4: 1 | D4: 1 | E4: 1 | F4: 1 | G4: 2 | H4: 2 | I4: 2 | J4: 2
A5: ST-LINK boards | C5: 2 | D5: 3 | E5: 4 | F5: 5 | G5: 2 | H5: 3 | I5: 4 | J5: 5
A6: DigiKey PN | B6: Description | C6: Line incl. VAT | D6: Line incl. VAT | E6: Line incl. VAT | F6: Line incl. VAT | G6: Line incl. VAT | H6: Line incl. VAT | I6: Line incl. VAT | J6: Line incl. VAT
A7: ='DigiKey Order'!A4 -> 490-GRM31CR61A107MEA8LCT-ND | B7: ='DigiKey Order'!D4 -> CAP CER 100UF 10V X5R 1206 | C7: =IF(OR('DigiKey Order'!$L$4<>"Y",(MAX(0,'DigiKey Order'!$F$4*C$4+'DigiKey Order'!$H$4*C$5-'DigiKey Order'!$K$4)+'DigiKey Order'!$M$4)<=0),0,(MAX(0,'DigiKey Order'!$F$4*C$4+'DigiKey Order'!$H$4*C$5-'DigiKey Order'!$K$4)+'DigiKey Order'!$M$4)*IF('DigiKey Order'!$P$4<>"",'DigiKey Order'!$P$4,LOOKUP((MAX(0,'DigiKey Order'!$F$4*C$4+'DigiKey Order'!$H$4*C$5-'DigiKey Order'!$K$4)+'DigiKey Order'!$M$4),'DigiKey Order'!$U$4:$AB$4,'DigiKey Order'!$AC$4:$AJ$4))*(1+Settings!$B$7)) -> 0 | D7: =IF(OR('DigiKey Order'!$L$4<>"Y",(MAX(0,'DigiKey Order'!$F$4*D$4+'DigiKey Order'!$H$4*D$5-'DigiKey Order'!$K$4)+'DigiKey Order'!$M$4)<=0),0,(MAX(0,'DigiKey Order'!$F$4*D$4+'DigiKey Order'!$H$4*D$5-'DigiKey Order'!$K$4)+'DigiKey Order'!$M$4)*IF('DigiKey Order'!$P$4<>"",'DigiKey Order'!$P$4,LOOKUP((MAX(0,'DigiKey Order'!$F$4*D$4+'DigiKey Order'!$H$4*D$5-'DigiKey Order'!$K$4)+'DigiKey Order'!$M$4),'DigiKey Order'!$U$4:$AB$4,'DigiKey Order'!$AC$4:$AJ$4))*(1+Settings!$B$7)) -> 0 | E7: =IF(OR('DigiKey Order'!$L$4<>"Y",(MAX(0,'DigiKey Order'!$F$4*E$4+'DigiKey Order'!$H$4*E$5-'DigiKey Order'!$K$4)+'DigiKey Order'!$M$4)<=0),0,(MAX(0,'DigiKey Order'!$F$4*E$4+'DigiKey Order'!$H$4*E$5-'DigiKey Order'!$K$4)+'DigiKey Order'!$M$4)*IF('DigiKey Order'!$P$4<>"",'DigiKey Order'!$P$4,LOOKUP((MAX(0,'DigiKey Order'!$F$4*E$4+'DigiKey Order'!$H$4*E$5-'DigiKey Order'!$K$4)+'DigiKey Order'!$M$4),'DigiKey Order'!$U$4:$AB$4,'DigiKey Order'!$AC$4:$AJ$4))*(1+Settings!$B$7)) -> 0 | F7: =IF(OR('DigiKey Order'!$L$4<>"Y",(MAX(0,'DigiKey Order'!$F$4*F$4+'DigiKey Order'!$H$4*F$5-'DigiKey Order'!$K$4)+'DigiKey Order'!$M$4)<=0),0,(MAX(0,'DigiKey Order'!$F$4*F$4+'DigiKey Order'!$H$4*F$5-'DigiKey Order'!$K$4)+'DigiKey Order'!$M$4)*IF('DigiKey Order'!$P$4<>"",'DigiKey Order'!$P$4,LOOKUP((MAX(0,'DigiKey Order'!$F$4*F$4+'DigiKey Order'!$H$4*F$5-'DigiKey Order'!$K$4)+'DigiKey Order'!$M$4),'DigiKey Order'!$U$4:$AB$4,'DigiKey Order'!$AC$4:$AJ$4))*(1+Settings!$B$7)) -> 0 | G7: =IF(OR('DigiKey Order'!$L$4<>"Y",(MAX(0,'DigiKey Order'!$F$4*G$4+'DigiKey Order'!$H$4*G$5-'DigiKey Order'!$K$4)+'DigiKey Order'!$M$4)<=0),0,(MAX(0,'DigiKey Order'!$F$4*G$4+'DigiKey Order'!$H$4*G$5-'DigiKey Order'!$K$4)+'DigiKey Order'!$M$4)*IF('DigiKey Order'!$P$4<>"",'DigiKey Order'!$P$4,LOOKUP((MAX(0,'DigiKey Order'!$F$4*G$4+'DigiKey Order'!$H$4*G$5-'DigiKey Order'!$K$4)+'DigiKey Order'!$M$4),'DigiKey Order'!$U$4:$AB$4,'DigiKey Order'!$AC$4:$AJ$4))*(1+Settings!$B$7)) -> 0 | H7: =IF(OR('DigiKey Order'!$L$4<>"Y",(MAX(0,'DigiKey Order'!$F$4*H$4+'DigiKey Order'!$H$4*H$5-'DigiKey Order'!$K$4)+'DigiKey Order'!$M$4)<=0),0,(MAX(0,'DigiKey Order'!$F$4*H$4+'DigiKey Order'!$H$4*H$5-'DigiKey Order'!$K$4)+'DigiKey Order'!$M$4)*IF('DigiKey Order'!$P$4<>"",'DigiKey Order'!$P$4,LOOKUP((MAX(0,'DigiKey Order'!$F$4*H$4+'DigiKey Order'!$H$4*H$5-'DigiKey Order'!$K$4)+'DigiKey Order'!$M$4),'DigiKey Order'!$U$4:$AB$4,'DigiKey Order'!$AC$4:$AJ$4))*(1+Settings!$B$7)) -> 0 | I7: =IF(OR('DigiKey Order'!$L$4<>"Y",(MAX(0,'DigiKey Order'!$F$4*I$4+'DigiKey Order'!$H$4*I$5-'DigiKey Order'!$K$4)+'DigiKey Order'!$M$4)<=0),0,(MAX(0,'DigiKey Order'!$F$4*I$4+'DigiKey Order'!$H$4*I$5-'DigiKey Order'!$K$4)+'DigiKey Order'!$M$4)*IF('DigiKey Order'!$P$4<>"",'DigiKey Order'!$P$4,LOOKUP((MAX(0,'DigiKey Order'!$F$4*I$4+'DigiKey Order'!$H$4*I$5-'DigiKey Order'!$K$4)+'DigiKey Order'!$M$4),'DigiKey Order'!$U$4:$AB$4,'DigiKey Order'!$AC$4:$AJ$4))*(1+Settings!$B$7)) -> 0 | J7: =IF(OR('DigiKey Order'!$L$4<>"Y",(MAX(0,'DigiKey Order'!$F$4*J$4+'DigiKey Order'!$H$4*J$5-'DigiKey Order'!$K$4)+'DigiKey Order'!$M$4)<=0),0,(MAX(0,'DigiKey Order'!$F$4*J$4+'DigiKey Order'!$H$4*J$5-'DigiKey Order'!$K$4)+'DigiKey Order'!$M$4)*IF('DigiKey Order'!$P$4<>"",'DigiKey Order'!$P$4,LOOKUP((MAX(0,'DigiKey Order'!$F$4*J$4+'DigiKey Order'!$H$4*J$5-'DigiKey Order'!$K$4)+'DigiKey Order'!$M$4),'DigiKey Order'!$U$4:$AB$4,'DigiKey Order'!$AC$4:$AJ$4))*(1+Settings!$B$7)) -> 0
A8: ='DigiKey Order'!A5 -> 490-5869-1-ND | B8: ='DigiKey Order'!D5 -> CAP CER 27PF 50V C0G 0402 | C8: =IF(OR('DigiKey Order'!$L$5<>"Y",(MAX(0,'DigiKey Order'!$F$5*C$4+'DigiKey Order'!$H$5*C$5-'DigiKey Order'!$K$5)+'DigiKey Order'!$M$5)<=0),0,(MAX(0,'DigiKey Order'!$F$5*C$4+'DigiKey Order'!$H$5*C$5-'DigiKey Order'!$K$5)+'DigiKey Order'!$M$5)*IF('DigiKey Order'!$P$5<>"",'DigiKey Order'!$P$5,LOOKUP((MAX(0,'DigiKey Order'!$F$5*C$4+'DigiKey Order'!$H$5*C$5-'DigiKey Order'!$K$5)+'DigiKey Order'!$M$5),'DigiKey Order'!$U$5:$AB$5,'DigiKey Order'!$AC$5:$AJ$5))*(1+Settings!$B$7)) -> 1.725 | D8: =IF(OR('DigiKey Order'!$L$5<>"Y",(MAX(0,'DigiKey Order'!$F$5*D$4+'DigiKey Order'!$H$5*D$5-'DigiKey Order'!$K$5)+'DigiKey Order'!$M$5)<=0),0,(MAX(0,'DigiKey Order'!$F$5*D$4+'DigiKey Order'!$H$5*D$5-'DigiKey Order'!$K$5)+'DigiKey Order'!$M$5)*IF('DigiKey Order'!$P$5<>"",'DigiKey Order'!$P$5,LOOKUP((MAX(0,'DigiKey Order'!$F$5*D$4+'DigiKey Order'!$H$5*D$5-'DigiKey Order'!$K$5)+'DigiKey Order'!$M$5),'DigiKey Order'!$U$5:$AB$5,'DigiKey Order'!$AC$5:$AJ$5))*(1+Settings!$B$7)) -> 2.07 | E8: =IF(OR('DigiKey Order'!$L$5<>"Y",(MAX(0,'DigiKey Order'!$F$5*E$4+'DigiKey Order'!$H$5*E$5-'DigiKey Order'!$K$5)+'DigiKey Order'!$M$5)<=0),0,(MAX(0,'DigiKey Order'!$F$5*E$4+'DigiKey Order'!$H$5*E$5-'DigiKey Order'!$K$5)+'DigiKey Order'!$M$5)*IF('DigiKey Order'!$P$5<>"",'DigiKey Order'!$P$5,LOOKUP((MAX(0,'DigiKey Order'!$F$5*E$4+'DigiKey Order'!$H$5*E$5-'DigiKey Order'!$K$5)+'DigiKey Order'!$M$5),'DigiKey Order'!$U$5:$AB$5,'DigiKey Order'!$AC$5:$AJ$5))*(1+Settings!$B$7)) -> 2.415 | F8: =IF(OR('DigiKey Order'!$L$5<>"Y",(MAX(0,'DigiKey Order'!$F$5*F$4+'DigiKey Order'!$H$5*F$5-'DigiKey Order'!$K$5)+'DigiKey Order'!$M$5)<=0),0,(MAX(0,'DigiKey Order'!$F$5*F$4+'DigiKey Order'!$H$5*F$5-'DigiKey Order'!$K$5)+'DigiKey Order'!$M$5)*IF('DigiKey Order'!$P$5<>"",'DigiKey Order'!$P$5,LOOKUP((MAX(0,'DigiKey Order'!$F$5*F$4+'DigiKey Order'!$H$5*F$5-'DigiKey Order'!$K$5)+'DigiKey Order'!$M$5),'DigiKey Order'!$U$5:$AB$5,'DigiKey Order'!$AC$5:$AJ$5))*(1+Settings!$B$7)) -> 2.76 | G8: =IF(OR('DigiKey Order'!$L$5<>"Y",(MAX(0,'DigiKey Order'!$F$5*G$4+'DigiKey Order'!$H$5*G$5-'DigiKey Order'!$K$5)+'DigiKey Order'!$M$5)<=0),0,(MAX(0,'DigiKey Order'!$F$5*G$4+'DigiKey Order'!$H$5*G$5-'DigiKey Order'!$K$5)+'DigiKey Order'!$M$5)*IF('DigiKey Order'!$P$5<>"",'DigiKey Order'!$P$5,LOOKUP((MAX(0,'DigiKey Order'!$F$5*G$4+'DigiKey Order'!$H$5*G$5-'DigiKey Order'!$K$5)+'DigiKey Order'!$M$5),'DigiKey Order'!$U$5:$AB$5,'DigiKey Order'!$AC$5:$AJ$5))*(1+Settings!$B$7)) -> 1.725 | H8: =IF(OR('DigiKey Order'!$L$5<>"Y",(MAX(0,'DigiKey Order'!$F$5*H$4+'DigiKey Order'!$H$5*H$5-'DigiKey Order'!$K$5)+'DigiKey Order'!$M$5)<=0),0,(MAX(0,'DigiKey Order'!$F$5*H$4+'DigiKey Order'!$H$5*H$5-'DigiKey Order'!$K$5)+'DigiKey Order'!$M$5)*IF('DigiKey Order'!$P$5<>"",'DigiKey Order'!$P$5,LOOKUP((MAX(0,'DigiKey Order'!$F$5*H$4+'DigiKey Order'!$H$5*H$5-'DigiKey Order'!$K$5)+'DigiKey Order'!$M$5),'DigiKey Order'!$U$5:$AB$5,'DigiKey Order'!$AC$5:$AJ$5))*(1+Settings!$B$7)) -> 2.07 | I8: =IF(OR('DigiKey Order'!$L$5<>"Y",(MAX(0,'DigiKey Order'!$F$5*I$4+'DigiKey Order'!$H$5*I$5-'DigiKey Order'!$K$5)+'DigiKey Order'!$M$5)<=0),0,(MAX(0,'DigiKey Order'!$F$5*I$4+'DigiKey Order'!$H$5*I$5-'DigiKey Order'!$K$5)+'DigiKey Order'!$M$5)*IF('DigiKey Order'!$P$5<>"",'DigiKey Order'!$P$5,LOOKUP((MAX(0,'DigiKey Order'!$F$5*I$4+'DigiKey Order'!$H$5*I$5-'DigiKey Order'!$K$5)+'DigiKey Order'!$M$5),'DigiKey Order'!$U$5:$AB$5,'DigiKey Order'!$AC$5:$AJ$5))*(1+Settings!$B$7)) -> 2.415 | J8: =IF(OR('DigiKey Order'!$L$5<>"Y",(MAX(0,'DigiKey Order'!$F$5*J$4+'DigiKey Order'!$H$5*J$5-'DigiKey Order'!$K$5)+'DigiKey Order'!$M$5)<=0),0,(MAX(0,'DigiKey Order'!$F$5*J$4+'DigiKey Order'!$H$5*J$5-'DigiKey Order'!$K$5)+'DigiKey Order'!$M$5)*IF('DigiKey Order'!$P$5<>"",'DigiKey Order'!$P$5,LOOKUP((MAX(0,'DigiKey Order'!$F$5*J$4+'DigiKey Order'!$H$5*J$5-'DigiKey Order'!$K$5)+'DigiKey Order'!$M$5),'DigiKey Order'!$U$5:$AB$5,'DigiKey Order'!$AC$5:$AJ$5))*(1+Settings!$B$7)) -> 2.76
A9: ='DigiKey Order'!A6 -> RMCF0603FT5K10CT-ND | B9: ='DigiKey Order'!D6 -> RES 5.1K OHM 1% 1/10W 0603 | C9: =IF(OR('DigiKey Order'!$L$6<>"Y",(MAX(0,'DigiKey Order'!$F$6*C$4+'DigiKey Order'!$H$6*C$5-'DigiKey Order'!$K$6)+'DigiKey Order'!$M$6)<=0),0,(MAX(0,'DigiKey Order'!$F$6*C$4+'DigiKey Order'!$H$6*C$5-'DigiKey Order'!$K$6)+'DigiKey Order'!$M$6)*IF('DigiKey Order'!$P$6<>"",'DigiKey Order'!$P$6,LOOKUP((MAX(0,'DigiKey Order'!$F$6*C$4+'DigiKey Order'!$H$6*C$5-'DigiKey Order'!$K$6)+'DigiKey Order'!$M$6),'DigiKey Order'!$U$6:$AB$6,'DigiKey Order'!$AC$6:$AJ$6))*(1+Settings!$B$7)) -> 0 | D9: =IF(OR('DigiKey Order'!$L$6<>"Y",(MAX(0,'DigiKey Order'!$F$6*D$4+'DigiKey Order'!$H$6*D$5-'DigiKey Order'!$K$6)+'DigiKey Order'!$M$6)<=0),0,(MAX(0,'DigiKey Order'!$F$6*D$4+'DigiKey Order'!$H$6*D$5-'DigiKey Order'!$K$6)+'DigiKey Order'!$M$6)*IF('DigiKey Order'!$P$6<>"",'DigiKey Order'!$P$6,LOOKUP((MAX(0,'DigiKey Order'!$F$6*D$4+'DigiKey Order'!$H$6*D$5-'DigiKey Order'!$K$6)+'DigiKey Order'!$M$6),'DigiKey Order'!$U$6:$AB$6,'DigiKey Order'!$AC$6:$AJ$6))*(1+Settings!$B$7)) -> 0 | E9: =IF(OR('DigiKey Order'!$L$6<>"Y",(MAX(0,'DigiKey Order'!$F$6*E$4+'DigiKey Order'!$H$6*E$5-'DigiKey Order'!$K$6)+'DigiKey Order'!$M$6)<=0),0,(MAX(0,'DigiKey Order'!$F$6*E$4+'DigiKey Order'!$H$6*E$5-'DigiKey Order'!$K$6)+'DigiKey Order'!$M$6)*IF('DigiKey Order'!$P$6<>"",'DigiKey Order'!$P$6,LOOKUP((MAX(0,'DigiKey Order'!$F$6*E$4+'DigiKey Order'!$H$6*E$5-'DigiKey Order'!$K$6)+'DigiKey Order'!$M$6),'DigiKey Order'!$U$6:$AB$6,'DigiKey Order'!$AC$6:$AJ$6))*(1+Settings!$B$7)) -> 0 | F9: =IF(OR('DigiKey Order'!$L$6<>"Y",(MAX(0,'DigiKey Order'!$F$6*F$4+'DigiKey Order'!$H$6*F$5-'DigiKey Order'!$K$6)+'DigiKey Order'!$M$6)<=0),0,(MAX(0,'DigiKey Order'!$F$6*F$4+'DigiKey Order'!$H$6*F$5-'DigiKey Order'!$K$6)+'DigiKey Order'!$M$6)*IF('DigiKey Order'!$P$6<>"",'DigiKey Order'!$P$6,LOOKUP((MAX(0,'DigiKey Order'!$F$6*F$4+'DigiKey Order'!$H$6*F$5-'DigiKey Order'!$K$6)+'DigiKey Order'!$M$6),'DigiKey Order'!$U$6:$AB$6,'DigiKey Order'!$AC$6:$AJ$6))*(1+Settings!$B$7)) -> 0 | G9: =IF(OR('DigiKey Order'!$L$6<>"Y",(MAX(0,'DigiKey Order'!$F$6*G$4+'DigiKey Order'!$H$6*G$5-'DigiKey Order'!$K$6)+'DigiKey Order'!$M$6)<=0),0,(MAX(0,'DigiKey Order'!$F$6*G$4+'DigiKey Order'!$H$6*G$5-'DigiKey Order'!$K$6)+'DigiKey Order'!$M$6)*IF('DigiKey Order'!$P$6<>"",'DigiKey Order'!$P$6,LOOKUP((MAX(0,'DigiKey Order'!$F$6*G$4+'DigiKey Order'!$H$6*G$5-'DigiKey Order'!$K$6)+'DigiKey Order'!$M$6),'DigiKey Order'!$U$6:$AB$6,'DigiKey Order'!$AC$6:$AJ$6))*(1+Settings!$B$7)) -> 0 | H9: =IF(OR('DigiKey Order'!$L$6<>"Y",(MAX(0,'DigiKey Order'!$F$6*H$4+'DigiKey Order'!$H$6*H$5-'DigiKey Order'!$K$6)+'DigiKey Order'!$M$6)<=0),0,(MAX(0,'DigiKey Order'!$F$6*H$4+'DigiKey Order'!$H$6*H$5-'DigiKey Order'!$K$6)+'DigiKey Order'!$M$6)*IF('DigiKey Order'!$P$6<>"",'DigiKey Order'!$P$6,LOOKUP((MAX(0,'DigiKey Order'!$F$6*H$4+'DigiKey Order'!$H$6*H$5-'DigiKey Order'!$K$6)+'DigiKey Order'!$M$6),'DigiKey Order'!$U$6:$AB$6,'DigiKey Order'!$AC$6:$AJ$6))*(1+Settings!$B$7)) -> 0 | I9: =IF(OR('DigiKey Order'!$L$6<>"Y",(MAX(0,'DigiKey Order'!$F$6*I$4+'DigiKey Order'!$H$6*I$5-'DigiKey Order'!$K$6)+'DigiKey Order'!$M$6)<=0),0,(MAX(0,'DigiKey Order'!$F$6*I$4+'DigiKey Order'!$H$6*I$5-'DigiKey Order'!$K$6)+'DigiKey Order'!$M$6)*IF('DigiKey Order'!$P$6<>"",'DigiKey Order'!$P$6,LOOKUP((MAX(0,'DigiKey Order'!$F$6*I$4+'DigiKey Order'!$H$6*I$5-'DigiKey Order'!$K$6)+'DigiKey Order'!$M$6),'DigiKey Order'!$U$6:$AB$6,'DigiKey Order'!$AC$6:$AJ$6))*(1+Settings!$B$7)) -> 0 | J9: =IF(OR('DigiKey Order'!$L$6<>"Y",(MAX(0,'DigiKey Order'!$F$6*J$4+'DigiKey Order'!$H$6*J$5-'DigiKey Order'!$K$6)+'DigiKey Order'!$M$6)<=0),0,(MAX(0,'DigiKey Order'!$F$6*J$4+'DigiKey Order'!$H$6*J$5-'DigiKey Order'!$K$6)+'DigiKey Order'!$M$6)*IF('DigiKey Order'!$P$6<>"",'DigiKey Order'!$P$6,LOOKUP((MAX(0,'DigiKey Order'!$F$6*J$4+'DigiKey Order'!$H$6*J$5-'DigiKey Order'!$K$6)+'DigiKey Order'!$M$6),'DigiKey Order'!$U$6:$AB$6,'DigiKey Order'!$AC$6:$AJ$6))*(1+Settings!$B$7)) -> 0
A10: ='DigiKey Order'!A7 -> 475-LGQ976.01-MGNI-35-1CT-ND | B10: ='DigiKey Order'!D7 -> LED GREEN CLEAR 0603 SMD | C10: =IF(OR('DigiKey Order'!$L$7<>"Y",(MAX(0,'DigiKey Order'!$F$7*C$4+'DigiKey Order'!$H$7*C$5-'DigiKey Order'!$K$7)+'DigiKey Order'!$M$7)<=0),0,(MAX(0,'DigiKey Order'!$F$7*C$4+'DigiKey Order'!$H$7*C$5-'DigiKey Order'!$K$7)+'DigiKey Order'!$M$7)*IF('DigiKey Order'!$P$7<>"",'DigiKey Order'!$P$7,LOOKUP((MAX(0,'DigiKey Order'!$F$7*C$4+'DigiKey Order'!$H$7*C$5-'DigiKey Order'!$K$7)+'DigiKey Order'!$M$7),'DigiKey Order'!$U$7:$AB$7,'DigiKey Order'!$AC$7:$AJ$7))*(1+Settings!$B$7)) -> 0 | D10: =IF(OR('DigiKey Order'!$L$7<>"Y",(MAX(0,'DigiKey Order'!$F$7*D$4+'DigiKey Order'!$H$7*D$5-'DigiKey Order'!$K$7)+'DigiKey Order'!$M$7)<=0),0,(MAX(0,'DigiKey Order'!$F$7*D$4+'DigiKey Order'!$H$7*D$5-'DigiKey Order'!$K$7)+'DigiKey Order'!$M$7)*IF('DigiKey Order'!$P$7<>"",'DigiKey Order'!$P$7,LOOKUP((MAX(0,'DigiKey Order'!$F$7*D$4+'DigiKey Order'!$H$7*D$5-'DigiKey Order'!$K$7)+'DigiKey Order'!$M$7),'DigiKey Order'!$U$7:$AB$7,'DigiKey Order'!$AC$7:$AJ$7))*(1+Settings!$B$7)) -> 0 | E10: =IF(OR('DigiKey Order'!$L$7<>"Y",(MAX(0,'DigiKey Order'!$F$7*E$4+'DigiKey Order'!$H$7*E$5-'DigiKey Order'!$K$7)+'DigiKey Order'!$M$7)<=0),0,(MAX(0,'DigiKey Order'!$F$7*E$4+'DigiKey Order'!$H$7*E$5-'DigiKey Order'!$K$7)+'DigiKey Order'!$M$7)*IF('DigiKey Order'!$P$7<>"",'DigiKey Order'!$P$7,LOOKUP((MAX(0,'DigiKey Order'!$F$7*E$4+'DigiKey Order'!$H$7*E$5-'DigiKey Order'!$K$7)+'DigiKey Order'!$M$7),'DigiKey Order'!$U$7:$AB$7,'DigiKey Order'!$AC$7:$AJ$7))*(1+Settings!$B$7)) -> 0 | F10: =IF(OR('DigiKey Order'!$L$7<>"Y",(MAX(0,'DigiKey Order'!$F$7*F$4+'DigiKey Order'!$H$7*F$5-'DigiKey Order'!$K$7)+'DigiKey Order'!$M$7)<=0),0,(MAX(0,'DigiKey Order'!$F$7*F$4+'DigiKey Order'!$H$7*F$5-'DigiKey Order'!$K$7)+'DigiKey Order'!$M$7)*IF('DigiKey Order'!$P$7<>"",'DigiKey Order'!$P$7,LOOKUP((MAX(0,'DigiKey Order'!$F$7*F$4+'DigiKey Order'!$H$7*F$5-'DigiKey Order'!$K$7)+'DigiKey Order'!$M$7),'DigiKey Order'!$U$7:$AB$7,'DigiKey Order'!$AC$7:$AJ$7))*(1+Settings!$B$7)) -> 0 | G10: =IF(OR('DigiKey Order'!$L$7<>"Y",(MAX(0,'DigiKey Order'!$F$7*G$4+'DigiKey Order'!$H$7*G$5-'DigiKey Order'!$K$7)+'DigiKey Order'!$M$7)<=0),0,(MAX(0,'DigiKey Order'!$F$7*G$4+'DigiKey Order'!$H$7*G$5-'DigiKey Order'!$K$7)+'DigiKey Order'!$M$7)*IF('DigiKey Order'!$P$7<>"",'DigiKey Order'!$P$7,LOOKUP((MAX(0,'DigiKey Order'!$F$7*G$4+'DigiKey Order'!$H$7*G$5-'DigiKey Order'!$K$7)+'DigiKey Order'!$M$7),'DigiKey Order'!$U$7:$AB$7,'DigiKey Order'!$AC$7:$AJ$7))*(1+Settings!$B$7)) -> 0 | H10: =IF(OR('DigiKey Order'!$L$7<>"Y",(MAX(0,'DigiKey Order'!$F$7*H$4+'DigiKey Order'!$H$7*H$5-'DigiKey Order'!$K$7)+'DigiKey Order'!$M$7)<=0),0,(MAX(0,'DigiKey Order'!$F$7*H$4+'DigiKey Order'!$H$7*H$5-'DigiKey Order'!$K$7)+'DigiKey Order'!$M$7)*IF('DigiKey Order'!$P$7<>"",'DigiKey Order'!$P$7,LOOKUP((MAX(0,'DigiKey Order'!$F$7*H$4+'DigiKey Order'!$H$7*H$5-'DigiKey Order'!$K$7)+'DigiKey Order'!$M$7),'DigiKey Order'!$U$7:$AB$7,'DigiKey Order'!$AC$7:$AJ$7))*(1+Settings!$B$7)) -> 0 | I10: =IF(OR('DigiKey Order'!$L$7<>"Y",(MAX(0,'DigiKey Order'!$F$7*I$4+'DigiKey Order'!$H$7*I$5-'DigiKey Order'!$K$7)+'DigiKey Order'!$M$7)<=0),0,(MAX(0,'DigiKey Order'!$F$7*I$4+'DigiKey Order'!$H$7*I$5-'DigiKey Order'!$K$7)+'DigiKey Order'!$M$7)*IF('DigiKey Order'!$P$7<>"",'DigiKey Order'!$P$7,LOOKUP((MAX(0,'DigiKey Order'!$F$7*I$4+'DigiKey Order'!$H$7*I$5-'DigiKey Order'!$K$7)+'DigiKey Order'!$M$7),'DigiKey Order'!$U$7:$AB$7,'DigiKey Order'!$AC$7:$AJ$7))*(1+Settings!$B$7)) -> 0 | J10: =IF(OR('DigiKey Order'!$L$7<>"Y",(MAX(0,'DigiKey Order'!$F$7*J$4+'DigiKey Order'!$H$7*J$5-'DigiKey Order'!$K$7)+'DigiKey Order'!$M$7)<=0),0,(MAX(0,'DigiKey Order'!$F$7*J$4+'DigiKey Order'!$H$7*J$5-'DigiKey Order'!$K$7)+'DigiKey Order'!$M$7)*IF('DigiKey Order'!$P$7<>"",'DigiKey Order'!$P$7,LOOKUP((MAX(0,'DigiKey Order'!$F$7*J$4+'DigiKey Order'!$H$7*J$5-'DigiKey Order'!$K$7)+'DigiKey Order'!$M$7),'DigiKey Order'!$U$7:$AB$7,'DigiKey Order'!$AC$7:$AJ$7))*(1+Settings!$B$7)) -> 0
A11: ='DigiKey Order'!A8 -> 475-LOQ976.01-P2R2-25-1-20-R18CT-ND | B11: ='DigiKey Order'!D8 -> LED ORANGE CLEAR 0603 SMD | C11: =IF(OR('DigiKey Order'!$L$8<>"Y",(MAX(0,'DigiKey Order'!$F$8*C$4+'DigiKey Order'!$H$8*C$5-'DigiKey Order'!$K$8)+'DigiKey Order'!$M$8)<=0),0,(MAX(0,'DigiKey Order'!$F$8*C$4+'DigiKey Order'!$H$8*C$5-'DigiKey Order'!$K$8)+'DigiKey Order'!$M$8)*IF('DigiKey Order'!$P$8<>"",'DigiKey Order'!$P$8,LOOKUP((MAX(0,'DigiKey Order'!$F$8*C$4+'DigiKey Order'!$H$8*C$5-'DigiKey Order'!$K$8)+'DigiKey Order'!$M$8),'DigiKey Order'!$U$8:$AB$8,'DigiKey Order'!$AC$8:$AJ$8))*(1+Settings!$B$7)) -> 0 | D11: =IF(OR('DigiKey Order'!$L$8<>"Y",(MAX(0,'DigiKey Order'!$F$8*D$4+'DigiKey Order'!$H$8*D$5-'DigiKey Order'!$K$8)+'DigiKey Order'!$M$8)<=0),0,(MAX(0,'DigiKey Order'!$F$8*D$4+'DigiKey Order'!$H$8*D$5-'DigiKey Order'!$K$8)+'DigiKey Order'!$M$8)*IF('DigiKey Order'!$P$8<>"",'DigiKey Order'!$P$8,LOOKUP((MAX(0,'DigiKey Order'!$F$8*D$4+'DigiKey Order'!$H$8*D$5-'DigiKey Order'!$K$8)+'DigiKey Order'!$M$8),'DigiKey Order'!$U$8:$AB$8,'DigiKey Order'!$AC$8:$AJ$8))*(1+Settings!$B$7)) -> 0 | E11: =IF(OR('DigiKey Order'!$L$8<>"Y",(MAX(0,'DigiKey Order'!$F$8*E$4+'DigiKey Order'!$H$8*E$5-'DigiKey Order'!$K$8)+'DigiKey Order'!$M$8)<=0),0,(MAX(0,'DigiKey Order'!$F$8*E$4+'DigiKey Order'!$H$8*E$5-'DigiKey Order'!$K$8)+'DigiKey Order'!$M$8)*IF('DigiKey Order'!$P$8<>"",'DigiKey Order'!$P$8,LOOKUP((MAX(0,'DigiKey Order'!$F$8*E$4+'DigiKey Order'!$H$8*E$5-'DigiKey Order'!$K$8)+'DigiKey Order'!$M$8),'DigiKey Order'!$U$8:$AB$8,'DigiKey Order'!$AC$8:$AJ$8))*(1+Settings!$B$7)) -> 0 | F11: =IF(OR('DigiKey Order'!$L$8<>"Y",(MAX(0,'DigiKey Order'!$F$8*F$4+'DigiKey Order'!$H$8*F$5-'DigiKey Order'!$K$8)+'DigiKey Order'!$M$8)<=0),0,(MAX(0,'DigiKey Order'!$F$8*F$4+'DigiKey Order'!$H$8*F$5-'DigiKey Order'!$K$8)+'DigiKey Order'!$M$8)*IF('DigiKey Order'!$P$8<>"",'DigiKey Order'!$P$8,LOOKUP((MAX(0,'DigiKey Order'!$F$8*F$4+'DigiKey Order'!$H$8*F$5-'DigiKey Order'!$K$8)+'DigiKey Order'!$M$8),'DigiKey Order'!$U$8:$AB$8,'DigiKey Order'!$AC$8:$AJ$8))*(1+Settings!$B$7)) -> 0 | G11: =IF(OR('DigiKey Order'!$L$8<>"Y",(MAX(0,'DigiKey Order'!$F$8*G$4+'DigiKey Order'!$H$8*G$5-'DigiKey Order'!$K$8)+'DigiKey Order'!$M$8)<=0),0,(MAX(0,'DigiKey Order'!$F$8*G$4+'DigiKey Order'!$H$8*G$5-'DigiKey Order'!$K$8)+'DigiKey Order'!$M$8)*IF('DigiKey Order'!$P$8<>"",'DigiKey Order'!$P$8,LOOKUP((MAX(0,'DigiKey Order'!$F$8*G$4+'DigiKey Order'!$H$8*G$5-'DigiKey Order'!$K$8)+'DigiKey Order'!$M$8),'DigiKey Order'!$U$8:$AB$8,'DigiKey Order'!$AC$8:$AJ$8))*(1+Settings!$B$7)) -> 0 | H11: =IF(OR('DigiKey Order'!$L$8<>"Y",(MAX(0,'DigiKey Order'!$F$8*H$4+'DigiKey Order'!$H$8*H$5-'DigiKey Order'!$K$8)+'DigiKey Order'!$M$8)<=0),0,(MAX(0,'DigiKey Order'!$F$8*H$4+'DigiKey Order'!$H$8*H$5-'DigiKey Order'!$K$8)+'DigiKey Order'!$M$8)*IF('DigiKey Order'!$P$8<>"",'DigiKey Order'!$P$8,LOOKUP((MAX(0,'DigiKey Order'!$F$8*H$4+'DigiKey Order'!$H$8*H$5-'DigiKey Order'!$K$8)+'DigiKey Order'!$M$8),'DigiKey Order'!$U$8:$AB$8,'DigiKey Order'!$AC$8:$AJ$8))*(1+Settings!$B$7)) -> 0 | I11: =IF(OR('DigiKey Order'!$L$8<>"Y",(MAX(0,'DigiKey Order'!$F$8*I$4+'DigiKey Order'!$H$8*I$5-'DigiKey Order'!$K$8)+'DigiKey Order'!$M$8)<=0),0,(MAX(0,'DigiKey Order'!$F$8*I$4+'DigiKey Order'!$H$8*I$5-'DigiKey Order'!$K$8)+'DigiKey Order'!$M$8)*IF('DigiKey Order'!$P$8<>"",'DigiKey Order'!$P$8,LOOKUP((MAX(0,'DigiKey Order'!$F$8*I$4+'DigiKey Order'!$H$8*I$5-'DigiKey Order'!$K$8)+'DigiKey Order'!$M$8),'DigiKey Order'!$U$8:$AB$8,'DigiKey Order'!$AC$8:$AJ$8))*(1+Settings!$B$7)) -> 0 | J11: =IF(OR('DigiKey Order'!$L$8<>"Y",(MAX(0,'DigiKey Order'!$F$8*J$4+'DigiKey Order'!$H$8*J$5-'DigiKey Order'!$K$8)+'DigiKey Order'!$M$8)<=0),0,(MAX(0,'DigiKey Order'!$F$8*J$4+'DigiKey Order'!$H$8*J$5-'DigiKey Order'!$K$8)+'DigiKey Order'!$M$8)*IF('DigiKey Order'!$P$8<>"",'DigiKey Order'!$P$8,LOOKUP((MAX(0,'DigiKey Order'!$F$8*J$4+'DigiKey Order'!$H$8*J$5-'DigiKey Order'!$K$8)+'DigiKey Order'!$M$8),'DigiKey Order'!$U$8:$AB$8,'DigiKey Order'!$AC$8:$AJ$8))*(1+Settings!$B$7)) -> 0
A12: ='DigiKey Order'!A9 -> 900-2086581001CT-ND | B12: ='DigiKey Order'!D9 -> CONN RCPT HDMI V2.1 19POS SMD RA | C12: =IF(OR('DigiKey Order'!$L$9<>"Y",(MAX(0,'DigiKey Order'!$F$9*C$4+'DigiKey Order'!$H$9*C$5-'DigiKey Order'!$K$9)+'DigiKey Order'!$M$9)<=0),0,(MAX(0,'DigiKey Order'!$F$9*C$4+'DigiKey Order'!$H$9*C$5-'DigiKey Order'!$K$9)+'DigiKey Order'!$M$9)*IF('DigiKey Order'!$P$9<>"",'DigiKey Order'!$P$9,LOOKUP((MAX(0,'DigiKey Order'!$F$9*C$4+'DigiKey Order'!$H$9*C$5-'DigiKey Order'!$K$9)+'DigiKey Order'!$M$9),'DigiKey Order'!$U$9:$AB$9,'DigiKey Order'!$AC$9:$AJ$9))*(1+Settings!$B$7)) -> 70.9875 | D12: =IF(OR('DigiKey Order'!$L$9<>"Y",(MAX(0,'DigiKey Order'!$F$9*D$4+'DigiKey Order'!$H$9*D$5-'DigiKey Order'!$K$9)+'DigiKey Order'!$M$9)<=0),0,(MAX(0,'DigiKey Order'!$F$9*D$4+'DigiKey Order'!$H$9*D$5-'DigiKey Order'!$K$9)+'DigiKey Order'!$M$9)*IF('DigiKey Order'!$P$9<>"",'DigiKey Order'!$P$9,LOOKUP((MAX(0,'DigiKey Order'!$F$9*D$4+'DigiKey Order'!$H$9*D$5-'DigiKey Order'!$K$9)+'DigiKey Order'!$M$9),'DigiKey Order'!$U$9:$AB$9,'DigiKey Order'!$AC$9:$AJ$9))*(1+Settings!$B$7)) -> 70.9875 | E12: =IF(OR('DigiKey Order'!$L$9<>"Y",(MAX(0,'DigiKey Order'!$F$9*E$4+'DigiKey Order'!$H$9*E$5-'DigiKey Order'!$K$9)+'DigiKey Order'!$M$9)<=0),0,(MAX(0,'DigiKey Order'!$F$9*E$4+'DigiKey Order'!$H$9*E$5-'DigiKey Order'!$K$9)+'DigiKey Order'!$M$9)*IF('DigiKey Order'!$P$9<>"",'DigiKey Order'!$P$9,LOOKUP((MAX(0,'DigiKey Order'!$F$9*E$4+'DigiKey Order'!$H$9*E$5-'DigiKey Order'!$K$9)+'DigiKey Order'!$M$9),'DigiKey Order'!$U$9:$AB$9,'DigiKey Order'!$AC$9:$AJ$9))*(1+Settings!$B$7)) -> 70.9875 | F12: =IF(OR('DigiKey Order'!$L$9<>"Y",(MAX(0,'DigiKey Order'!$F$9*F$4+'DigiKey Order'!$H$9*F$5-'DigiKey Order'!$K$9)+'DigiKey Order'!$M$9)<=0),0,(MAX(0,'DigiKey Order'!$F$9*F$4+'DigiKey Order'!$H$9*F$5-'DigiKey Order'!$K$9)+'DigiKey Order'!$M$9)*IF('DigiKey Order'!$P$9<>"",'DigiKey Order'!$P$9,LOOKUP((MAX(0,'DigiKey Order'!$F$9*F$4+'DigiKey Order'!$H$9*F$5-'DigiKey Order'!$K$9)+'DigiKey Order'!$M$9),'DigiKey Order'!$U$9:$AB$9,'DigiKey Order'!$AC$9:$AJ$9))*(1+Settings!$B$7)) -> 70.9875 | G12: =IF(OR('DigiKey Order'!$L$9<>"Y",(MAX(0,'DigiKey Order'!$F$9*G$4+'DigiKey Order'!$H$9*G$5-'DigiKey Order'!$K$9)+'DigiKey Order'!$M$9)<=0),0,(MAX(0,'DigiKey Order'!$F$9*G$4+'DigiKey Order'!$H$9*G$5-'DigiKey Order'!$K$9)+'DigiKey Order'!$M$9)*IF('DigiKey Order'!$P$9<>"",'DigiKey Order'!$P$9,LOOKUP((MAX(0,'DigiKey Order'!$F$9*G$4+'DigiKey Order'!$H$9*G$5-'DigiKey Order'!$K$9)+'DigiKey Order'!$M$9),'DigiKey Order'!$U$9:$AB$9,'DigiKey Order'!$AC$9:$AJ$9))*(1+Settings!$B$7)) -> 141.975 | H12: =IF(OR('DigiKey Order'!$L$9<>"Y",(MAX(0,'DigiKey Order'!$F$9*H$4+'DigiKey Order'!$H$9*H$5-'DigiKey Order'!$K$9)+'DigiKey Order'!$M$9)<=0),0,(MAX(0,'DigiKey Order'!$F$9*H$4+'DigiKey Order'!$H$9*H$5-'DigiKey Order'!$K$9)+'DigiKey Order'!$M$9)*IF('DigiKey Order'!$P$9<>"",'DigiKey Order'!$P$9,LOOKUP((MAX(0,'DigiKey Order'!$F$9*H$4+'DigiKey Order'!$H$9*H$5-'DigiKey Order'!$K$9)+'DigiKey Order'!$M$9),'DigiKey Order'!$U$9:$AB$9,'DigiKey Order'!$AC$9:$AJ$9))*(1+Settings!$B$7)) -> 141.975 | I12: =IF(OR('DigiKey Order'!$L$9<>"Y",(MAX(0,'DigiKey Order'!$F$9*I$4+'DigiKey Order'!$H$9*I$5-'DigiKey Order'!$K$9)+'DigiKey Order'!$M$9)<=0),0,(MAX(0,'DigiKey Order'!$F$9*I$4+'DigiKey Order'!$H$9*I$5-'DigiKey Order'!$K$9)+'DigiKey Order'!$M$9)*IF('DigiKey Order'!$P$9<>"",'DigiKey Order'!$P$9,LOOKUP((MAX(0,'DigiKey Order'!$F$9*I$4+'DigiKey Order'!$H$9*I$5-'DigiKey Order'!$K$9)+'DigiKey Order'!$M$9),'DigiKey Order'!$U$9:$AB$9,'DigiKey Order'!$AC$9:$AJ$9))*(1+Settings!$B$7)) -> 141.975 | J12: =IF(OR('DigiKey Order'!$L$9<>"Y",(MAX(0,'DigiKey Order'!$F$9*J$4+'DigiKey Order'!$H$9*J$5-'DigiKey Order'!$K$9)+'DigiKey Order'!$M$9)<=0),0,(MAX(0,'DigiKey Order'!$F$9*J$4+'DigiKey Order'!$H$9*J$5-'DigiKey Order'!$K$9)+'DigiKey Order'!$M$9)*IF('DigiKey Order'!$P$9<>"",'DigiKey Order'!$P$9,LOOKUP((MAX(0,'DigiKey Order'!$F$9*J$4+'DigiKey Order'!$H$9*J$5-'DigiKey Order'!$K$9)+'DigiKey Order'!$M$9),'DigiKey Order'!$U$9:$AB$9,'DigiKey Order'!$AC$9:$AJ$9))*(1+Settings!$B$7)) -> 141.975
A13: ='DigiKey Order'!A10 -> 2073-USB4105-GF-ACT-ND | B13: ='DigiKey Order'!D10 -> CONN RCP USB2.0 TYPE-C 16P SMD RA | C13: =IF(OR('DigiKey Order'!$L$10<>"Y",(MAX(0,'DigiKey Order'!$F$10*C$4+'DigiKey Order'!$H$10*C$5-'DigiKey Order'!$K$10)+'DigiKey Order'!$M$10)<=0),0,(MAX(0,'DigiKey Order'!$F$10*C$4+'DigiKey Order'!$H$10*C$5-'DigiKey Order'!$K$10)+'DigiKey Order'!$M$10)*IF('DigiKey Order'!$P$10<>"",'DigiKey Order'!$P$10,LOOKUP((MAX(0,'DigiKey Order'!$F$10*C$4+'DigiKey Order'!$H$10*C$5-'DigiKey Order'!$K$10)+'DigiKey Order'!$M$10),'DigiKey Order'!$U$10:$AB$10,'DigiKey Order'!$AC$10:$AJ$10))*(1+Settings!$B$7)) -> 13.1 | D13: =IF(OR('DigiKey Order'!$L$10<>"Y",(MAX(0,'DigiKey Order'!$F$10*D$4+'DigiKey Order'!$H$10*D$5-'DigiKey Order'!$K$10)+'DigiKey Order'!$M$10)<=0),0,(MAX(0,'DigiKey Order'!$F$10*D$4+'DigiKey Order'!$H$10*D$5-'DigiKey Order'!$K$10)+'DigiKey Order'!$M$10)*IF('DigiKey Order'!$P$10<>"",'DigiKey Order'!$P$10,LOOKUP((MAX(0,'DigiKey Order'!$F$10*D$4+'DigiKey Order'!$H$10*D$5-'DigiKey Order'!$K$10)+'DigiKey Order'!$M$10),'DigiKey Order'!$U$10:$AB$10,'DigiKey Order'!$AC$10:$AJ$10))*(1+Settings!$B$7)) -> 13.1 | E13: =IF(OR('DigiKey Order'!$L$10<>"Y",(MAX(0,'DigiKey Order'!$F$10*E$4+'DigiKey Order'!$H$10*E$5-'DigiKey Order'!$K$10)+'DigiKey Order'!$M$10)<=0),0,(MAX(0,'DigiKey Order'!$F$10*E$4+'DigiKey Order'!$H$10*E$5-'DigiKey Order'!$K$10)+'DigiKey Order'!$M$10)*IF('DigiKey Order'!$P$10<>"",'DigiKey Order'!$P$10,LOOKUP((MAX(0,'DigiKey Order'!$F$10*E$4+'DigiKey Order'!$H$10*E$5-'DigiKey Order'!$K$10)+'DigiKey Order'!$M$10),'DigiKey Order'!$U$10:$AB$10,'DigiKey Order'!$AC$10:$AJ$10))*(1+Settings!$B$7)) -> 13.1 | F13: =IF(OR('DigiKey Order'!$L$10<>"Y",(MAX(0,'DigiKey Order'!$F$10*F$4+'DigiKey Order'!$H$10*F$5-'DigiKey Order'!$K$10)+'DigiKey Order'!$M$10)<=0),0,(MAX(0,'DigiKey Order'!$F$10*F$4+'DigiKey Order'!$H$10*F$5-'DigiKey Order'!$K$10)+'DigiKey Order'!$M$10)*IF('DigiKey Order'!$P$10<>"",'DigiKey Order'!$P$10,LOOKUP((MAX(0,'DigiKey Order'!$F$10*F$4+'DigiKey Order'!$H$10*F$5-'DigiKey Order'!$K$10)+'DigiKey Order'!$M$10),'DigiKey Order'!$U$10:$AB$10,'DigiKey Order'!$AC$10:$AJ$10))*(1+Settings!$B$7)) -> 19.65 | G13: =IF(OR('DigiKey Order'!$L$10<>"Y",(MAX(0,'DigiKey Order'!$F$10*G$4+'DigiKey Order'!$H$10*G$5-'DigiKey Order'!$K$10)+'DigiKey Order'!$M$10)<=0),0,(MAX(0,'DigiKey Order'!$F$10*G$4+'DigiKey Order'!$H$10*G$5-'DigiKey Order'!$K$10)+'DigiKey Order'!$M$10)*IF('DigiKey Order'!$P$10<>"",'DigiKey Order'!$P$10,LOOKUP((MAX(0,'DigiKey Order'!$F$10*G$4+'DigiKey Order'!$H$10*G$5-'DigiKey Order'!$K$10)+'DigiKey Order'!$M$10),'DigiKey Order'!$U$10:$AB$10,'DigiKey Order'!$AC$10:$AJ$10))*(1+Settings!$B$7)) -> 19.65 | H13: =IF(OR('DigiKey Order'!$L$10<>"Y",(MAX(0,'DigiKey Order'!$F$10*H$4+'DigiKey Order'!$H$10*H$5-'DigiKey Order'!$K$10)+'DigiKey Order'!$M$10)<=0),0,(MAX(0,'DigiKey Order'!$F$10*H$4+'DigiKey Order'!$H$10*H$5-'DigiKey Order'!$K$10)+'DigiKey Order'!$M$10)*IF('DigiKey Order'!$P$10<>"",'DigiKey Order'!$P$10,LOOKUP((MAX(0,'DigiKey Order'!$F$10*H$4+'DigiKey Order'!$H$10*H$5-'DigiKey Order'!$K$10)+'DigiKey Order'!$M$10),'DigiKey Order'!$U$10:$AB$10,'DigiKey Order'!$AC$10:$AJ$10))*(1+Settings!$B$7)) -> 26.2 | I13: =IF(OR('DigiKey Order'!$L$10<>"Y",(MAX(0,'DigiKey Order'!$F$10*I$4+'DigiKey Order'!$H$10*I$5-'DigiKey Order'!$K$10)+'DigiKey Order'!$M$10)<=0),0,(MAX(0,'DigiKey Order'!$F$10*I$4+'DigiKey Order'!$H$10*I$5-'DigiKey Order'!$K$10)+'DigiKey Order'!$M$10)*IF('DigiKey Order'!$P$10<>"",'DigiKey Order'!$P$10,LOOKUP((MAX(0,'DigiKey Order'!$F$10*I$4+'DigiKey Order'!$H$10*I$5-'DigiKey Order'!$K$10)+'DigiKey Order'!$M$10),'DigiKey Order'!$U$10:$AB$10,'DigiKey Order'!$AC$10:$AJ$10))*(1+Settings!$B$7)) -> 32.75 | J13: =IF(OR('DigiKey Order'!$L$10<>"Y",(MAX(0,'DigiKey Order'!$F$10*J$4+'DigiKey Order'!$H$10*J$5-'DigiKey Order'!$K$10)+'DigiKey Order'!$M$10)<=0),0,(MAX(0,'DigiKey Order'!$F$10*J$4+'DigiKey Order'!$H$10*J$5-'DigiKey Order'!$K$10)+'DigiKey Order'!$M$10)*IF('DigiKey Order'!$P$10<>"",'DigiKey Order'!$P$10,LOOKUP((MAX(0,'DigiKey Order'!$F$10*J$4+'DigiKey Order'!$H$10*J$5-'DigiKey Order'!$K$10)+'DigiKey Order'!$M$10),'DigiKey Order'!$U$10:$AB$10,'DigiKey Order'!$AC$10:$AJ$10))*(1+Settings!$B$7)) -> 39.3
A14: ='DigiKey Order'!A11 -> 732-2107-ND | B14: ='DigiKey Order'!D11 -> CONN RCPT USB2.0 TYPE-A STACKED R/A | C14: =IF(OR('DigiKey Order'!$L$11<>"Y",(MAX(0,'DigiKey Order'!$F$11*C$4+'DigiKey Order'!$H$11*C$5-'DigiKey Order'!$K$11)+'DigiKey Order'!$M$11)<=0),0,(MAX(0,'DigiKey Order'!$F$11*C$4+'DigiKey Order'!$H$11*C$5-'DigiKey Order'!$K$11)+'DigiKey Order'!$M$11)*IF('DigiKey Order'!$P$11<>"",'DigiKey Order'!$P$11,LOOKUP((MAX(0,'DigiKey Order'!$F$11*C$4+'DigiKey Order'!$H$11*C$5-'DigiKey Order'!$K$11)+'DigiKey Order'!$M$11),'DigiKey Order'!$U$11:$AB$11,'DigiKey Order'!$AC$11:$AJ$11))*(1+Settings!$B$7)) -> 32.75 | D14: =IF(OR('DigiKey Order'!$L$11<>"Y",(MAX(0,'DigiKey Order'!$F$11*D$4+'DigiKey Order'!$H$11*D$5-'DigiKey Order'!$K$11)+'DigiKey Order'!$M$11)<=0),0,(MAX(0,'DigiKey Order'!$F$11*D$4+'DigiKey Order'!$H$11*D$5-'DigiKey Order'!$K$11)+'DigiKey Order'!$M$11)*IF('DigiKey Order'!$P$11<>"",'DigiKey Order'!$P$11,LOOKUP((MAX(0,'DigiKey Order'!$F$11*D$4+'DigiKey Order'!$H$11*D$5-'DigiKey Order'!$K$11)+'DigiKey Order'!$M$11),'DigiKey Order'!$U$11:$AB$11,'DigiKey Order'!$AC$11:$AJ$11))*(1+Settings!$B$7)) -> 32.75 | E14: =IF(OR('DigiKey Order'!$L$11<>"Y",(MAX(0,'DigiKey Order'!$F$11*E$4+'DigiKey Order'!$H$11*E$5-'DigiKey Order'!$K$11)+'DigiKey Order'!$M$11)<=0),0,(MAX(0,'DigiKey Order'!$F$11*E$4+'DigiKey Order'!$H$11*E$5-'DigiKey Order'!$K$11)+'DigiKey Order'!$M$11)*IF('DigiKey Order'!$P$11<>"",'DigiKey Order'!$P$11,LOOKUP((MAX(0,'DigiKey Order'!$F$11*E$4+'DigiKey Order'!$H$11*E$5-'DigiKey Order'!$K$11)+'DigiKey Order'!$M$11),'DigiKey Order'!$U$11:$AB$11,'DigiKey Order'!$AC$11:$AJ$11))*(1+Settings!$B$7)) -> 32.75 | F14: =IF(OR('DigiKey Order'!$L$11<>"Y",(MAX(0,'DigiKey Order'!$F$11*F$4+'DigiKey Order'!$H$11*F$5-'DigiKey Order'!$K$11)+'DigiKey Order'!$M$11)<=0),0,(MAX(0,'DigiKey Order'!$F$11*F$4+'DigiKey Order'!$H$11*F$5-'DigiKey Order'!$K$11)+'DigiKey Order'!$M$11)*IF('DigiKey Order'!$P$11<>"",'DigiKey Order'!$P$11,LOOKUP((MAX(0,'DigiKey Order'!$F$11*F$4+'DigiKey Order'!$H$11*F$5-'DigiKey Order'!$K$11)+'DigiKey Order'!$M$11),'DigiKey Order'!$U$11:$AB$11,'DigiKey Order'!$AC$11:$AJ$11))*(1+Settings!$B$7)) -> 32.75 | G14: =IF(OR('DigiKey Order'!$L$11<>"Y",(MAX(0,'DigiKey Order'!$F$11*G$4+'DigiKey Order'!$H$11*G$5-'DigiKey Order'!$K$11)+'DigiKey Order'!$M$11)<=0),0,(MAX(0,'DigiKey Order'!$F$11*G$4+'DigiKey Order'!$H$11*G$5-'DigiKey Order'!$K$11)+'DigiKey Order'!$M$11)*IF('DigiKey Order'!$P$11<>"",'DigiKey Order'!$P$11,LOOKUP((MAX(0,'DigiKey Order'!$F$11*G$4+'DigiKey Order'!$H$11*G$5-'DigiKey Order'!$K$11)+'DigiKey Order'!$M$11),'DigiKey Order'!$U$11:$AB$11,'DigiKey Order'!$AC$11:$AJ$11))*(1+Settings!$B$7)) -> 65.5 | H14: =IF(OR('DigiKey Order'!$L$11<>"Y",(MAX(0,'DigiKey Order'!$F$11*H$4+'DigiKey Order'!$H$11*H$5-'DigiKey Order'!$K$11)+'DigiKey Order'!$M$11)<=0),0,(MAX(0,'DigiKey Order'!$F$11*H$4+'DigiKey Order'!$H$11*H$5-'DigiKey Order'!$K$11)+'DigiKey Order'!$M$11)*IF('DigiKey Order'!$P$11<>"",'DigiKey Order'!$P$11,LOOKUP((MAX(0,'DigiKey Order'!$F$11*H$4+'DigiKey Order'!$H$11*H$5-'DigiKey Order'!$K$11)+'DigiKey Order'!$M$11),'DigiKey Order'!$U$11:$AB$11,'DigiKey Order'!$AC$11:$AJ$11))*(1+Settings!$B$7)) -> 65.5 | I14: =IF(OR('DigiKey Order'!$L$11<>"Y",(MAX(0,'DigiKey Order'!$F$11*I$4+'DigiKey Order'!$H$11*I$5-'DigiKey Order'!$K$11)+'DigiKey Order'!$M$11)<=0),0,(MAX(0,'DigiKey Order'!$F$11*I$4+'DigiKey Order'!$H$11*I$5-'DigiKey Order'!$K$11)+'DigiKey Order'!$M$11)*IF('DigiKey Order'!$P$11<>"",'DigiKey Order'!$P$11,LOOKUP((MAX(0,'DigiKey Order'!$F$11*I$4+'DigiKey Order'!$H$11*I$5-'DigiKey Order'!$K$11)+'DigiKey Order'!$M$11),'DigiKey Order'!$U$11:$AB$11,'DigiKey Order'!$AC$11:$AJ$11))*(1+Settings!$B$7)) -> 65.5 | J14: =IF(OR('DigiKey Order'!$L$11<>"Y",(MAX(0,'DigiKey Order'!$F$11*J$4+'DigiKey Order'!$H$11*J$5-'DigiKey Order'!$K$11)+'DigiKey Order'!$M$11)<=0),0,(MAX(0,'DigiKey Order'!$F$11*J$4+'DigiKey Order'!$H$11*J$5-'DigiKey Order'!$K$11)+'DigiKey Order'!$M$11)*IF('DigiKey Order'!$P$11<>"",'DigiKey Order'!$P$11,LOOKUP((MAX(0,'DigiKey Order'!$F$11*J$4+'DigiKey Order'!$H$11*J$5-'DigiKey Order'!$K$11)+'DigiKey Order'!$M$11),'DigiKey Order'!$U$11:$AB$11,'DigiKey Order'!$AC$11:$AJ$11))*(1+Settings!$B$7)) -> 65.5
A15: ='DigiKey Order'!A12 -> 732-5317-ND | B15: ='DigiKey Order'!D12 -> CONN HEADER VERT 4POS 2.54MM | C15: =IF(OR('DigiKey Order'!$L$12<>"Y",(MAX(0,'DigiKey Order'!$F$12*C$4+'DigiKey Order'!$H$12*C$5-'DigiKey Order'!$K$12)+'DigiKey Order'!$M$12)<=0),0,(MAX(0,'DigiKey Order'!$F$12*C$4+'DigiKey Order'!$H$12*C$5-'DigiKey Order'!$K$12)+'DigiKey Order'!$M$12)*IF('DigiKey Order'!$P$12<>"",'DigiKey Order'!$P$12,LOOKUP((MAX(0,'DigiKey Order'!$F$12*C$4+'DigiKey Order'!$H$12*C$5-'DigiKey Order'!$K$12)+'DigiKey Order'!$M$12),'DigiKey Order'!$U$12:$AB$12,'DigiKey Order'!$AC$12:$AJ$12))*(1+Settings!$B$7)) -> 0 | D15: =IF(OR('DigiKey Order'!$L$12<>"Y",(MAX(0,'DigiKey Order'!$F$12*D$4+'DigiKey Order'!$H$12*D$5-'DigiKey Order'!$K$12)+'DigiKey Order'!$M$12)<=0),0,(MAX(0,'DigiKey Order'!$F$12*D$4+'DigiKey Order'!$H$12*D$5-'DigiKey Order'!$K$12)+'DigiKey Order'!$M$12)*IF('DigiKey Order'!$P$12<>"",'DigiKey Order'!$P$12,LOOKUP((MAX(0,'DigiKey Order'!$F$12*D$4+'DigiKey Order'!$H$12*D$5-'DigiKey Order'!$K$12)+'DigiKey Order'!$M$12),'DigiKey Order'!$U$12:$AB$12,'DigiKey Order'!$AC$12:$AJ$12))*(1+Settings!$B$7)) -> 0 | E15: =IF(OR('DigiKey Order'!$L$12<>"Y",(MAX(0,'DigiKey Order'!$F$12*E$4+'DigiKey Order'!$H$12*E$5-'DigiKey Order'!$K$12)+'DigiKey Order'!$M$12)<=0),0,(MAX(0,'DigiKey Order'!$F$12*E$4+'DigiKey Order'!$H$12*E$5-'DigiKey Order'!$K$12)+'DigiKey Order'!$M$12)*IF('DigiKey Order'!$P$12<>"",'DigiKey Order'!$P$12,LOOKUP((MAX(0,'DigiKey Order'!$F$12*E$4+'DigiKey Order'!$H$12*E$5-'DigiKey Order'!$K$12)+'DigiKey Order'!$M$12),'DigiKey Order'!$U$12:$AB$12,'DigiKey Order'!$AC$12:$AJ$12))*(1+Settings!$B$7)) -> 0 | F15: =IF(OR('DigiKey Order'!$L$12<>"Y",(MAX(0,'DigiKey Order'!$F$12*F$4+'DigiKey Order'!$H$12*F$5-'DigiKey Order'!$K$12)+'DigiKey Order'!$M$12)<=0),0,(MAX(0,'DigiKey Order'!$F$12*F$4+'DigiKey Order'!$H$12*F$5-'DigiKey Order'!$K$12)+'DigiKey Order'!$M$12)*IF('DigiKey Order'!$P$12<>"",'DigiKey Order'!$P$12,LOOKUP((MAX(0,'DigiKey Order'!$F$12*F$4+'DigiKey Order'!$H$12*F$5-'DigiKey Order'!$K$12)+'DigiKey Order'!$M$12),'DigiKey Order'!$U$12:$AB$12,'DigiKey Order'!$AC$12:$AJ$12))*(1+Settings!$B$7)) -> 0 | G15: =IF(OR('DigiKey Order'!$L$12<>"Y",(MAX(0,'DigiKey Order'!$F$12*G$4+'DigiKey Order'!$H$12*G$5-'DigiKey Order'!$K$12)+'DigiKey Order'!$M$12)<=0),0,(MAX(0,'DigiKey Order'!$F$12*G$4+'DigiKey Order'!$H$12*G$5-'DigiKey Order'!$K$12)+'DigiKey Order'!$M$12)*IF('DigiKey Order'!$P$12<>"",'DigiKey Order'!$P$12,LOOKUP((MAX(0,'DigiKey Order'!$F$12*G$4+'DigiKey Order'!$H$12*G$5-'DigiKey Order'!$K$12)+'DigiKey Order'!$M$12),'DigiKey Order'!$U$12:$AB$12,'DigiKey Order'!$AC$12:$AJ$12))*(1+Settings!$B$7)) -> 0 | H15: =IF(OR('DigiKey Order'!$L$12<>"Y",(MAX(0,'DigiKey Order'!$F$12*H$4+'DigiKey Order'!$H$12*H$5-'DigiKey Order'!$K$12)+'DigiKey Order'!$M$12)<=0),0,(MAX(0,'DigiKey Order'!$F$12*H$4+'DigiKey Order'!$H$12*H$5-'DigiKey Order'!$K$12)+'DigiKey Order'!$M$12)*IF('DigiKey Order'!$P$12<>"",'DigiKey Order'!$P$12,LOOKUP((MAX(0,'DigiKey Order'!$F$12*H$4+'DigiKey Order'!$H$12*H$5-'DigiKey Order'!$K$12)+'DigiKey Order'!$M$12),'DigiKey Order'!$U$12:$AB$12,'DigiKey Order'!$AC$12:$AJ$12))*(1+Settings!$B$7)) -> 0 | I15: =IF(OR('DigiKey Order'!$L$12<>"Y",(MAX(0,'DigiKey Order'!$F$12*I$4+'DigiKey Order'!$H$12*I$5-'DigiKey Order'!$K$12)+'DigiKey Order'!$M$12)<=0),0,(MAX(0,'DigiKey Order'!$F$12*I$4+'DigiKey Order'!$H$12*I$5-'DigiKey Order'!$K$12)+'DigiKey Order'!$M$12)*IF('DigiKey Order'!$P$12<>"",'DigiKey Order'!$P$12,LOOKUP((MAX(0,'DigiKey Order'!$F$12*I$4+'DigiKey Order'!$H$12*I$5-'DigiKey Order'!$K$12)+'DigiKey Order'!$M$12),'DigiKey Order'!$U$12:$AB$12,'DigiKey Order'!$AC$12:$AJ$12))*(1+Settings!$B$7)) -> 0 | J15: =IF(OR('DigiKey Order'!$L$12<>"Y",(MAX(0,'DigiKey Order'!$F$12*J$4+'DigiKey Order'!$H$12*J$5-'DigiKey Order'!$K$12)+'DigiKey Order'!$M$12)<=0),0,(MAX(0,'DigiKey Order'!$F$12*J$4+'DigiKey Order'!$H$12*J$5-'DigiKey Order'!$K$12)+'DigiKey Order'!$M$12)*IF('DigiKey Order'!$P$12<>"",'DigiKey Order'!$P$12,LOOKUP((MAX(0,'DigiKey Order'!$F$12*J$4+'DigiKey Order'!$H$12*J$5-'DigiKey Order'!$K$12)+'DigiKey Order'!$M$12),'DigiKey Order'!$U$12:$AB$12,'DigiKey Order'!$AC$12:$AJ$12))*(1+Settings!$B$7)) -> 0
A16: ='DigiKey Order'!A13 -> 296-43875-1-ND | B16: ='DigiKey Order'!D13 -> TVS DIODE 3.6VWM 8.8VC 10USON | C16: =IF(OR('DigiKey Order'!$L$13<>"Y",(MAX(0,'DigiKey Order'!$F$13*C$4+'DigiKey Order'!$H$13*C$5-'DigiKey Order'!$K$13)+'DigiKey Order'!$M$13)<=0),0,(MAX(0,'DigiKey Order'!$F$13*C$4+'DigiKey Order'!$H$13*C$5-'DigiKey Order'!$K$13)+'DigiKey Order'!$M$13)*IF('DigiKey Order'!$P$13<>"",'DigiKey Order'!$P$13,LOOKUP((MAX(0,'DigiKey Order'!$F$13*C$4+'DigiKey Order'!$H$13*C$5-'DigiKey Order'!$K$13)+'DigiKey Order'!$M$13),'DigiKey Order'!$U$13:$AB$13,'DigiKey Order'!$AC$13:$AJ$13))*(1+Settings!$B$7)) -> 62.5075 | D16: =IF(OR('DigiKey Order'!$L$13<>"Y",(MAX(0,'DigiKey Order'!$F$13*D$4+'DigiKey Order'!$H$13*D$5-'DigiKey Order'!$K$13)+'DigiKey Order'!$M$13)<=0),0,(MAX(0,'DigiKey Order'!$F$13*D$4+'DigiKey Order'!$H$13*D$5-'DigiKey Order'!$K$13)+'DigiKey Order'!$M$13)*IF('DigiKey Order'!$P$13<>"",'DigiKey Order'!$P$13,LOOKUP((MAX(0,'DigiKey Order'!$F$13*D$4+'DigiKey Order'!$H$13*D$5-'DigiKey Order'!$K$13)+'DigiKey Order'!$M$13),'DigiKey Order'!$U$13:$AB$13,'DigiKey Order'!$AC$13:$AJ$13))*(1+Settings!$B$7)) -> 62.5075 | E16: =IF(OR('DigiKey Order'!$L$13<>"Y",(MAX(0,'DigiKey Order'!$F$13*E$4+'DigiKey Order'!$H$13*E$5-'DigiKey Order'!$K$13)+'DigiKey Order'!$M$13)<=0),0,(MAX(0,'DigiKey Order'!$F$13*E$4+'DigiKey Order'!$H$13*E$5-'DigiKey Order'!$K$13)+'DigiKey Order'!$M$13)*IF('DigiKey Order'!$P$13<>"",'DigiKey Order'!$P$13,LOOKUP((MAX(0,'DigiKey Order'!$F$13*E$4+'DigiKey Order'!$H$13*E$5-'DigiKey Order'!$K$13)+'DigiKey Order'!$M$13),'DigiKey Order'!$U$13:$AB$13,'DigiKey Order'!$AC$13:$AJ$13))*(1+Settings!$B$7)) -> 62.5075 | F16: =IF(OR('DigiKey Order'!$L$13<>"Y",(MAX(0,'DigiKey Order'!$F$13*F$4+'DigiKey Order'!$H$13*F$5-'DigiKey Order'!$K$13)+'DigiKey Order'!$M$13)<=0),0,(MAX(0,'DigiKey Order'!$F$13*F$4+'DigiKey Order'!$H$13*F$5-'DigiKey Order'!$K$13)+'DigiKey Order'!$M$13)*IF('DigiKey Order'!$P$13<>"",'DigiKey Order'!$P$13,LOOKUP((MAX(0,'DigiKey Order'!$F$13*F$4+'DigiKey Order'!$H$13*F$5-'DigiKey Order'!$K$13)+'DigiKey Order'!$M$13),'DigiKey Order'!$U$13:$AB$13,'DigiKey Order'!$AC$13:$AJ$13))*(1+Settings!$B$7)) -> 62.5075 | G16: =IF(OR('DigiKey Order'!$L$13<>"Y",(MAX(0,'DigiKey Order'!$F$13*G$4+'DigiKey Order'!$H$13*G$5-'DigiKey Order'!$K$13)+'DigiKey Order'!$M$13)<=0),0,(MAX(0,'DigiKey Order'!$F$13*G$4+'DigiKey Order'!$H$13*G$5-'DigiKey Order'!$K$13)+'DigiKey Order'!$M$13)*IF('DigiKey Order'!$P$13<>"",'DigiKey Order'!$P$13,LOOKUP((MAX(0,'DigiKey Order'!$F$13*G$4+'DigiKey Order'!$H$13*G$5-'DigiKey Order'!$K$13)+'DigiKey Order'!$M$13),'DigiKey Order'!$U$13:$AB$13,'DigiKey Order'!$AC$13:$AJ$13))*(1+Settings!$B$7)) -> 113.65 | H16: =IF(OR('DigiKey Order'!$L$13<>"Y",(MAX(0,'DigiKey Order'!$F$13*H$4+'DigiKey Order'!$H$13*H$5-'DigiKey Order'!$K$13)+'DigiKey Order'!$M$13)<=0),0,(MAX(0,'DigiKey Order'!$F$13*H$4+'DigiKey Order'!$H$13*H$5-'DigiKey Order'!$K$13)+'DigiKey Order'!$M$13)*IF('DigiKey Order'!$P$13<>"",'DigiKey Order'!$P$13,LOOKUP((MAX(0,'DigiKey Order'!$F$13*H$4+'DigiKey Order'!$H$13*H$5-'DigiKey Order'!$K$13)+'DigiKey Order'!$M$13),'DigiKey Order'!$U$13:$AB$13,'DigiKey Order'!$AC$13:$AJ$13))*(1+Settings!$B$7)) -> 113.65 | I16: =IF(OR('DigiKey Order'!$L$13<>"Y",(MAX(0,'DigiKey Order'!$F$13*I$4+'DigiKey Order'!$H$13*I$5-'DigiKey Order'!$K$13)+'DigiKey Order'!$M$13)<=0),0,(MAX(0,'DigiKey Order'!$F$13*I$4+'DigiKey Order'!$H$13*I$5-'DigiKey Order'!$K$13)+'DigiKey Order'!$M$13)*IF('DigiKey Order'!$P$13<>"",'DigiKey Order'!$P$13,LOOKUP((MAX(0,'DigiKey Order'!$F$13*I$4+'DigiKey Order'!$H$13*I$5-'DigiKey Order'!$K$13)+'DigiKey Order'!$M$13),'DigiKey Order'!$U$13:$AB$13,'DigiKey Order'!$AC$13:$AJ$13))*(1+Settings!$B$7)) -> 113.65 | J16: =IF(OR('DigiKey Order'!$L$13<>"Y",(MAX(0,'DigiKey Order'!$F$13*J$4+'DigiKey Order'!$H$13*J$5-'DigiKey Order'!$K$13)+'DigiKey Order'!$M$13)<=0),0,(MAX(0,'DigiKey Order'!$F$13*J$4+'DigiKey Order'!$H$13*J$5-'DigiKey Order'!$K$13)+'DigiKey Order'!$M$13)*IF('DigiKey Order'!$P$13<>"",'DigiKey Order'!$P$13,LOOKUP((MAX(0,'DigiKey Order'!$F$13*J$4+'DigiKey Order'!$H$13*J$5-'DigiKey Order'!$K$13)+'DigiKey Order'!$M$13),'DigiKey Order'!$U$13:$AB$13,'DigiKey Order'!$AC$13:$AJ$13))*(1+Settings!$B$7)) -> 113.65
A17: ='DigiKey Order'!A14 -> 296-42335-1-ND | B17: ='DigiKey Order'!D14 -> IC DISPLAYPORT 2:1 DIFF SW 56QFN | C17: =IF(OR('DigiKey Order'!$L$14<>"Y",(MAX(0,'DigiKey Order'!$F$14*C$4+'DigiKey Order'!$H$14*C$5-'DigiKey Order'!$K$14)+'DigiKey Order'!$M$14)<=0),0,(MAX(0,'DigiKey Order'!$F$14*C$4+'DigiKey Order'!$H$14*C$5-'DigiKey Order'!$K$14)+'DigiKey Order'!$M$14)*IF('DigiKey Order'!$P$14<>"",'DigiKey Order'!$P$14,LOOKUP((MAX(0,'DigiKey Order'!$F$14*C$4+'DigiKey Order'!$H$14*C$5-'DigiKey Order'!$K$14)+'DigiKey Order'!$M$14),'DigiKey Order'!$U$14:$AB$14,'DigiKey Order'!$AC$14:$AJ$14))*(1+Settings!$B$7)) -> 38.4 | D17: =IF(OR('DigiKey Order'!$L$14<>"Y",(MAX(0,'DigiKey Order'!$F$14*D$4+'DigiKey Order'!$H$14*D$5-'DigiKey Order'!$K$14)+'DigiKey Order'!$M$14)<=0),0,(MAX(0,'DigiKey Order'!$F$14*D$4+'DigiKey Order'!$H$14*D$5-'DigiKey Order'!$K$14)+'DigiKey Order'!$M$14)*IF('DigiKey Order'!$P$14<>"",'DigiKey Order'!$P$14,LOOKUP((MAX(0,'DigiKey Order'!$F$14*D$4+'DigiKey Order'!$H$14*D$5-'DigiKey Order'!$K$14)+'DigiKey Order'!$M$14),'DigiKey Order'!$U$14:$AB$14,'DigiKey Order'!$AC$14:$AJ$14))*(1+Settings!$B$7)) -> 38.4 | E17: =IF(OR('DigiKey Order'!$L$14<>"Y",(MAX(0,'DigiKey Order'!$F$14*E$4+'DigiKey Order'!$H$14*E$5-'DigiKey Order'!$K$14)+'DigiKey Order'!$M$14)<=0),0,(MAX(0,'DigiKey Order'!$F$14*E$4+'DigiKey Order'!$H$14*E$5-'DigiKey Order'!$K$14)+'DigiKey Order'!$M$14)*IF('DigiKey Order'!$P$14<>"",'DigiKey Order'!$P$14,LOOKUP((MAX(0,'DigiKey Order'!$F$14*E$4+'DigiKey Order'!$H$14*E$5-'DigiKey Order'!$K$14)+'DigiKey Order'!$M$14),'DigiKey Order'!$U$14:$AB$14,'DigiKey Order'!$AC$14:$AJ$14))*(1+Settings!$B$7)) -> 38.4 | F17: =IF(OR('DigiKey Order'!$L$14<>"Y",(MAX(0,'DigiKey Order'!$F$14*F$4+'DigiKey Order'!$H$14*F$5-'DigiKey Order'!$K$14)+'DigiKey Order'!$M$14)<=0),0,(MAX(0,'DigiKey Order'!$F$14*F$4+'DigiKey Order'!$H$14*F$5-'DigiKey Order'!$K$14)+'DigiKey Order'!$M$14)*IF('DigiKey Order'!$P$14<>"",'DigiKey Order'!$P$14,LOOKUP((MAX(0,'DigiKey Order'!$F$14*F$4+'DigiKey Order'!$H$14*F$5-'DigiKey Order'!$K$14)+'DigiKey Order'!$M$14),'DigiKey Order'!$U$14:$AB$14,'DigiKey Order'!$AC$14:$AJ$14))*(1+Settings!$B$7)) -> 38.4 | G17: =IF(OR('DigiKey Order'!$L$14<>"Y",(MAX(0,'DigiKey Order'!$F$14*G$4+'DigiKey Order'!$H$14*G$5-'DigiKey Order'!$K$14)+'DigiKey Order'!$M$14)<=0),0,(MAX(0,'DigiKey Order'!$F$14*G$4+'DigiKey Order'!$H$14*G$5-'DigiKey Order'!$K$14)+'DigiKey Order'!$M$14)*IF('DigiKey Order'!$P$14<>"",'DigiKey Order'!$P$14,LOOKUP((MAX(0,'DigiKey Order'!$F$14*G$4+'DigiKey Order'!$H$14*G$5-'DigiKey Order'!$K$14)+'DigiKey Order'!$M$14),'DigiKey Order'!$U$14:$AB$14,'DigiKey Order'!$AC$14:$AJ$14))*(1+Settings!$B$7)) -> 76.8 | H17: =IF(OR('DigiKey Order'!$L$14<>"Y",(MAX(0,'DigiKey Order'!$F$14*H$4+'DigiKey Order'!$H$14*H$5-'DigiKey Order'!$K$14)+'DigiKey Order'!$M$14)<=0),0,(MAX(0,'DigiKey Order'!$F$14*H$4+'DigiKey Order'!$H$14*H$5-'DigiKey Order'!$K$14)+'DigiKey Order'!$M$14)*IF('DigiKey Order'!$P$14<>"",'DigiKey Order'!$P$14,LOOKUP((MAX(0,'DigiKey Order'!$F$14*H$4+'DigiKey Order'!$H$14*H$5-'DigiKey Order'!$K$14)+'DigiKey Order'!$M$14),'DigiKey Order'!$U$14:$AB$14,'DigiKey Order'!$AC$14:$AJ$14))*(1+Settings!$B$7)) -> 76.8 | I17: =IF(OR('DigiKey Order'!$L$14<>"Y",(MAX(0,'DigiKey Order'!$F$14*I$4+'DigiKey Order'!$H$14*I$5-'DigiKey Order'!$K$14)+'DigiKey Order'!$M$14)<=0),0,(MAX(0,'DigiKey Order'!$F$14*I$4+'DigiKey Order'!$H$14*I$5-'DigiKey Order'!$K$14)+'DigiKey Order'!$M$14)*IF('DigiKey Order'!$P$14<>"",'DigiKey Order'!$P$14,LOOKUP((MAX(0,'DigiKey Order'!$F$14*I$4+'DigiKey Order'!$H$14*I$5-'DigiKey Order'!$K$14)+'DigiKey Order'!$M$14),'DigiKey Order'!$U$14:$AB$14,'DigiKey Order'!$AC$14:$AJ$14))*(1+Settings!$B$7)) -> 76.8 | J17: =IF(OR('DigiKey Order'!$L$14<>"Y",(MAX(0,'DigiKey Order'!$F$14*J$4+'DigiKey Order'!$H$14*J$5-'DigiKey Order'!$K$14)+'DigiKey Order'!$M$14)<=0),0,(MAX(0,'DigiKey Order'!$F$14*J$4+'DigiKey Order'!$H$14*J$5-'DigiKey Order'!$K$14)+'DigiKey Order'!$M$14)*IF('DigiKey Order'!$P$14<>"",'DigiKey Order'!$P$14,LOOKUP((MAX(0,'DigiKey Order'!$F$14*J$4+'DigiKey Order'!$H$14*J$5-'DigiKey Order'!$K$14)+'DigiKey Order'!$M$14),'DigiKey Order'!$U$14:$AB$14,'DigiKey Order'!$AC$14:$AJ$14))*(1+Settings!$B$7)) -> 76.8
A18: ='DigiKey Order'!A15 -> 296-50411-1-ND | B18: ='DigiKey Order'!D15 -> IC REG LINEAR 3.3V 500MA SOT23-5 | C18: =IF(OR('DigiKey Order'!$L$15<>"Y",(MAX(0,'DigiKey Order'!$F$15*C$4+'DigiKey Order'!$H$15*C$5-'DigiKey Order'!$K$15)+'DigiKey Order'!$M$15)<=0),0,(MAX(0,'DigiKey Order'!$F$15*C$4+'DigiKey Order'!$H$15*C$5-'DigiKey Order'!$K$15)+'DigiKey Order'!$M$15)*IF('DigiKey Order'!$P$15<>"",'DigiKey Order'!$P$15,LOOKUP((MAX(0,'DigiKey Order'!$F$15*C$4+'DigiKey Order'!$H$15*C$5-'DigiKey Order'!$K$15)+'DigiKey Order'!$M$15),'DigiKey Order'!$U$15:$AB$15,'DigiKey Order'!$AC$15:$AJ$15))*(1+Settings!$B$7)) -> 30.9375 | D18: =IF(OR('DigiKey Order'!$L$15<>"Y",(MAX(0,'DigiKey Order'!$F$15*D$4+'DigiKey Order'!$H$15*D$5-'DigiKey Order'!$K$15)+'DigiKey Order'!$M$15)<=0),0,(MAX(0,'DigiKey Order'!$F$15*D$4+'DigiKey Order'!$H$15*D$5-'DigiKey Order'!$K$15)+'DigiKey Order'!$M$15)*IF('DigiKey Order'!$P$15<>"",'DigiKey Order'!$P$15,LOOKUP((MAX(0,'DigiKey Order'!$F$15*D$4+'DigiKey Order'!$H$15*D$5-'DigiKey Order'!$K$15)+'DigiKey Order'!$M$15),'DigiKey Order'!$U$15:$AB$15,'DigiKey Order'!$AC$15:$AJ$15))*(1+Settings!$B$7)) -> 23.9875 | E18: =IF(OR('DigiKey Order'!$L$15<>"Y",(MAX(0,'DigiKey Order'!$F$15*E$4+'DigiKey Order'!$H$15*E$5-'DigiKey Order'!$K$15)+'DigiKey Order'!$M$15)<=0),0,(MAX(0,'DigiKey Order'!$F$15*E$4+'DigiKey Order'!$H$15*E$5-'DigiKey Order'!$K$15)+'DigiKey Order'!$M$15)*IF('DigiKey Order'!$P$15<>"",'DigiKey Order'!$P$15,LOOKUP((MAX(0,'DigiKey Order'!$F$15*E$4+'DigiKey Order'!$H$15*E$5-'DigiKey Order'!$K$15)+'DigiKey Order'!$M$15),'DigiKey Order'!$U$15:$AB$15,'DigiKey Order'!$AC$15:$AJ$15))*(1+Settings!$B$7)) -> 26.38625 | F18: =IF(OR('DigiKey Order'!$L$15<>"Y",(MAX(0,'DigiKey Order'!$F$15*F$4+'DigiKey Order'!$H$15*F$5-'DigiKey Order'!$K$15)+'DigiKey Order'!$M$15)<=0),0,(MAX(0,'DigiKey Order'!$F$15*F$4+'DigiKey Order'!$H$15*F$5-'DigiKey Order'!$K$15)+'DigiKey Order'!$M$15)*IF('DigiKey Order'!$P$15<>"",'DigiKey Order'!$P$15,LOOKUP((MAX(0,'DigiKey Order'!$F$15*F$4+'DigiKey Order'!$H$15*F$5-'DigiKey Order'!$K$15)+'DigiKey Order'!$M$15),'DigiKey Order'!$U$15:$AB$15,'DigiKey Order'!$AC$15:$AJ$15))*(1+Settings!$B$7)) -> 28.785 | G18: =IF(OR('DigiKey Order'!$L$15<>"Y",(MAX(0,'DigiKey Order'!$F$15*G$4+'DigiKey Order'!$H$15*G$5-'DigiKey Order'!$K$15)+'DigiKey Order'!$M$15)<=0),0,(MAX(0,'DigiKey Order'!$F$15*G$4+'DigiKey Order'!$H$15*G$5-'DigiKey Order'!$K$15)+'DigiKey Order'!$M$15)*IF('DigiKey Order'!$P$15<>"",'DigiKey Order'!$P$15,LOOKUP((MAX(0,'DigiKey Order'!$F$15*G$4+'DigiKey Order'!$H$15*G$5-'DigiKey Order'!$K$15)+'DigiKey Order'!$M$15),'DigiKey Order'!$U$15:$AB$15,'DigiKey Order'!$AC$15:$AJ$15))*(1+Settings!$B$7)) -> 23.9875 | H18: =IF(OR('DigiKey Order'!$L$15<>"Y",(MAX(0,'DigiKey Order'!$F$15*H$4+'DigiKey Order'!$H$15*H$5-'DigiKey Order'!$K$15)+'DigiKey Order'!$M$15)<=0),0,(MAX(0,'DigiKey Order'!$F$15*H$4+'DigiKey Order'!$H$15*H$5-'DigiKey Order'!$K$15)+'DigiKey Order'!$M$15)*IF('DigiKey Order'!$P$15<>"",'DigiKey Order'!$P$15,LOOKUP((MAX(0,'DigiKey Order'!$F$15*H$4+'DigiKey Order'!$H$15*H$5-'DigiKey Order'!$K$15)+'DigiKey Order'!$M$15),'DigiKey Order'!$U$15:$AB$15,'DigiKey Order'!$AC$15:$AJ$15))*(1+Settings!$B$7)) -> 26.38625 | I18: =IF(OR('DigiKey Order'!$L$15<>"Y",(MAX(0,'DigiKey Order'!$F$15*I$4+'DigiKey Order'!$H$15*I$5-'DigiKey Order'!$K$15)+'DigiKey Order'!$M$15)<=0),0,(MAX(0,'DigiKey Order'!$F$15*I$4+'DigiKey Order'!$H$15*I$5-'DigiKey Order'!$K$15)+'DigiKey Order'!$M$15)*IF('DigiKey Order'!$P$15<>"",'DigiKey Order'!$P$15,LOOKUP((MAX(0,'DigiKey Order'!$F$15*I$4+'DigiKey Order'!$H$15*I$5-'DigiKey Order'!$K$15)+'DigiKey Order'!$M$15),'DigiKey Order'!$U$15:$AB$15,'DigiKey Order'!$AC$15:$AJ$15))*(1+Settings!$B$7)) -> 28.785 | J18: =IF(OR('DigiKey Order'!$L$15<>"Y",(MAX(0,'DigiKey Order'!$F$15*J$4+'DigiKey Order'!$H$15*J$5-'DigiKey Order'!$K$15)+'DigiKey Order'!$M$15)<=0),0,(MAX(0,'DigiKey Order'!$F$15*J$4+'DigiKey Order'!$H$15*J$5-'DigiKey Order'!$K$15)+'DigiKey Order'!$M$15)*IF('DigiKey Order'!$P$15<>"",'DigiKey Order'!$P$15,LOOKUP((MAX(0,'DigiKey Order'!$F$15*J$4+'DigiKey Order'!$H$15*J$5-'DigiKey Order'!$K$15)+'DigiKey Order'!$M$15),'DigiKey Order'!$U$15:$AB$15,'DigiKey Order'!$AC$15:$AJ$15))*(1+Settings!$B$7)) -> 31.18375
A19: ='DigiKey Order'!A16 -> 497-STM32C031G6U6-ND | B19: ='DigiKey Order'!D16 -> IC MCU 32BIT 32KB FLASH 28UFQFPN | C19: =IF(OR('DigiKey Order'!$L$16<>"Y",(MAX(0,'DigiKey Order'!$F$16*C$4+'DigiKey Order'!$H$16*C$5-'DigiKey Order'!$K$16)+'DigiKey Order'!$M$16)<=0),0,(MAX(0,'DigiKey Order'!$F$16*C$4+'DigiKey Order'!$H$16*C$5-'DigiKey Order'!$K$16)+'DigiKey Order'!$M$16)*IF('DigiKey Order'!$P$16<>"",'DigiKey Order'!$P$16,LOOKUP((MAX(0,'DigiKey Order'!$F$16*C$4+'DigiKey Order'!$H$16*C$5-'DigiKey Order'!$K$16)+'DigiKey Order'!$M$16),'DigiKey Order'!$U$16:$AB$16,'DigiKey Order'!$AC$16:$AJ$16))*(1+Settings!$B$7)) -> 22.925 | D19: =IF(OR('DigiKey Order'!$L$16<>"Y",(MAX(0,'DigiKey Order'!$F$16*D$4+'DigiKey Order'!$H$16*D$5-'DigiKey Order'!$K$16)+'DigiKey Order'!$M$16)<=0),0,(MAX(0,'DigiKey Order'!$F$16*D$4+'DigiKey Order'!$H$16*D$5-'DigiKey Order'!$K$16)+'DigiKey Order'!$M$16)*IF('DigiKey Order'!$P$16<>"",'DigiKey Order'!$P$16,LOOKUP((MAX(0,'DigiKey Order'!$F$16*D$4+'DigiKey Order'!$H$16*D$5-'DigiKey Order'!$K$16)+'DigiKey Order'!$M$16),'DigiKey Order'!$U$16:$AB$16,'DigiKey Order'!$AC$16:$AJ$16))*(1+Settings!$B$7)) -> 22.925 | E19: =IF(OR('DigiKey Order'!$L$16<>"Y",(MAX(0,'DigiKey Order'!$F$16*E$4+'DigiKey Order'!$H$16*E$5-'DigiKey Order'!$K$16)+'DigiKey Order'!$M$16)<=0),0,(MAX(0,'DigiKey Order'!$F$16*E$4+'DigiKey Order'!$H$16*E$5-'DigiKey Order'!$K$16)+'DigiKey Order'!$M$16)*IF('DigiKey Order'!$P$16<>"",'DigiKey Order'!$P$16,LOOKUP((MAX(0,'DigiKey Order'!$F$16*E$4+'DigiKey Order'!$H$16*E$5-'DigiKey Order'!$K$16)+'DigiKey Order'!$M$16),'DigiKey Order'!$U$16:$AB$16,'DigiKey Order'!$AC$16:$AJ$16))*(1+Settings!$B$7)) -> 22.925 | F19: =IF(OR('DigiKey Order'!$L$16<>"Y",(MAX(0,'DigiKey Order'!$F$16*F$4+'DigiKey Order'!$H$16*F$5-'DigiKey Order'!$K$16)+'DigiKey Order'!$M$16)<=0),0,(MAX(0,'DigiKey Order'!$F$16*F$4+'DigiKey Order'!$H$16*F$5-'DigiKey Order'!$K$16)+'DigiKey Order'!$M$16)*IF('DigiKey Order'!$P$16<>"",'DigiKey Order'!$P$16,LOOKUP((MAX(0,'DigiKey Order'!$F$16*F$4+'DigiKey Order'!$H$16*F$5-'DigiKey Order'!$K$16)+'DigiKey Order'!$M$16),'DigiKey Order'!$U$16:$AB$16,'DigiKey Order'!$AC$16:$AJ$16))*(1+Settings!$B$7)) -> 22.925 | G19: =IF(OR('DigiKey Order'!$L$16<>"Y",(MAX(0,'DigiKey Order'!$F$16*G$4+'DigiKey Order'!$H$16*G$5-'DigiKey Order'!$K$16)+'DigiKey Order'!$M$16)<=0),0,(MAX(0,'DigiKey Order'!$F$16*G$4+'DigiKey Order'!$H$16*G$5-'DigiKey Order'!$K$16)+'DigiKey Order'!$M$16)*IF('DigiKey Order'!$P$16<>"",'DigiKey Order'!$P$16,LOOKUP((MAX(0,'DigiKey Order'!$F$16*G$4+'DigiKey Order'!$H$16*G$5-'DigiKey Order'!$K$16)+'DigiKey Order'!$M$16),'DigiKey Order'!$U$16:$AB$16,'DigiKey Order'!$AC$16:$AJ$16))*(1+Settings!$B$7)) -> 34.3875 | H19: =IF(OR('DigiKey Order'!$L$16<>"Y",(MAX(0,'DigiKey Order'!$F$16*H$4+'DigiKey Order'!$H$16*H$5-'DigiKey Order'!$K$16)+'DigiKey Order'!$M$16)<=0),0,(MAX(0,'DigiKey Order'!$F$16*H$4+'DigiKey Order'!$H$16*H$5-'DigiKey Order'!$K$16)+'DigiKey Order'!$M$16)*IF('DigiKey Order'!$P$16<>"",'DigiKey Order'!$P$16,LOOKUP((MAX(0,'DigiKey Order'!$F$16*H$4+'DigiKey Order'!$H$16*H$5-'DigiKey Order'!$K$16)+'DigiKey Order'!$M$16),'DigiKey Order'!$U$16:$AB$16,'DigiKey Order'!$AC$16:$AJ$16))*(1+Settings!$B$7)) -> 34.3875 | I19: =IF(OR('DigiKey Order'!$L$16<>"Y",(MAX(0,'DigiKey Order'!$F$16*I$4+'DigiKey Order'!$H$16*I$5-'DigiKey Order'!$K$16)+'DigiKey Order'!$M$16)<=0),0,(MAX(0,'DigiKey Order'!$F$16*I$4+'DigiKey Order'!$H$16*I$5-'DigiKey Order'!$K$16)+'DigiKey Order'!$M$16)*IF('DigiKey Order'!$P$16<>"",'DigiKey Order'!$P$16,LOOKUP((MAX(0,'DigiKey Order'!$F$16*I$4+'DigiKey Order'!$H$16*I$5-'DigiKey Order'!$K$16)+'DigiKey Order'!$M$16),'DigiKey Order'!$U$16:$AB$16,'DigiKey Order'!$AC$16:$AJ$16))*(1+Settings!$B$7)) -> 34.3875 | J19: =IF(OR('DigiKey Order'!$L$16<>"Y",(MAX(0,'DigiKey Order'!$F$16*J$4+'DigiKey Order'!$H$16*J$5-'DigiKey Order'!$K$16)+'DigiKey Order'!$M$16)<=0),0,(MAX(0,'DigiKey Order'!$F$16*J$4+'DigiKey Order'!$H$16*J$5-'DigiKey Order'!$K$16)+'DigiKey Order'!$M$16)*IF('DigiKey Order'!$P$16<>"",'DigiKey Order'!$P$16,LOOKUP((MAX(0,'DigiKey Order'!$F$16*J$4+'DigiKey Order'!$H$16*J$5-'DigiKey Order'!$K$16)+'DigiKey Order'!$M$16),'DigiKey Order'!$U$16:$AB$16,'DigiKey Order'!$AC$16:$AJ$16))*(1+Settings!$B$7)) -> 34.3875
